<?xml version="1.0" encoding="utf-8"?>
<!-- This URDF was automatically created by SolidWorks to URDF Exporter! Originally created by Stephen Brawner (brawner@gmail.com) 
     Commit Version: 1.5.1-0-g916b5db  Build Version: 1.5.7152.31018
     For more information, please see http://wiki.ros.org/sw_urdf_exporter -->
<robot
  name="gofa" xmlns:xacro="http://ros.org/wiki/xacro">
<link
    name="base_link">
    <inertial>
      <origin
        xyz="0.0 0.0 0.0"
        rpy="0 0 0" />
      <mass
        value="1.0" />
      <inertia
        ixx="10"
        ixy="0"
        ixz="0"
        iyy="10"
        iyz="0"
        izz="10" />
    </inertial>
    <visual>
      <origin
        xyz="0 0 0"
        rpy="0 0 0" />
      <geometry>
        <mesh
          filename="base_link.STL" />
      </geometry>
      <material
        name="">
        <color
          rgba="0.44 0.5 0.56 1" />
      </material>
    </visual>
    <collision>
      <origin
        xyz="0 0 0"
        rpy="0 0 0" />
      <geometry>
        <mesh
          filename="base_link.STL" />
      </geometry>
    </collision>
  </link>
<link
    name="link1">
    <inertial>
      <origin
        xyz="0.0 0.0 0.0"
        rpy="0 0 0" />
      <mass
        value="2.0" />
      <inertia
        ixx="10"
        ixy="0"
        ixz="0"
        iyy="10"
        iyz="0"
        izz="10" />
    </inertial>
    <visual>
      <origin
        xyz="0 0 0"
        rpy="0 0 0" />
      <geometry>
        <mesh
          filename="link1.STL" />
      </geometry>
      <material
        name="">
        <color
          rgba="0.83 0.83 0.83 1" />
      </material>
    </visual>
    <collision>
      <origin
        xyz="0 0 0"
        rpy="0 0 0" />
      <geometry>
        <mesh
          filename="link1.STL" />
      </geometry>
    </collision>
  </link>

   <joint
    name="joint1"
    type="revolute">
    <origin
      xyz="0 0 0.1865"
      rpy="0 0 0" />
    <parent
      link="base_link" />
    <child
      link="link1" />
    <axis
      xyz="0 0 1" />
    <limit
      lower="-2.7453"
      upper="2.7925"
      effort="200"
      velocity="200" />
  </joint>

<link
    name="link2">
    <inertial>
      <origin
        xyz="0.0 0.0 0.0"
        rpy="0 0 0" />
      <mass
        value="2.0" />
      <inertia
        ixx="10"
        ixy="0"
        ixz="0"
        iyy="10"
        iyz="0"
        izz="10" />
    </inertial>
    <visual>
      <origin
        xyz="0 0 0"
        rpy="0 0 0" />
      <geometry>
        <mesh
          filename="link2.STL" />
      </geometry>
      <material
        name="">
        <color
          rgba="0.83 0.83 0.83 1" />
      </material>
    </visual>
    <collision>
      <origin
        xyz="0 0 0"
        rpy="0 0 0" />
      <geometry>
        <mesh
          filename="link2.STL" />
      </geometry>
    </collision>
  </link>

   <joint
    name="joint2"
    type="revolute">
    <origin
      xyz="0 -0.086 0.07652"
      rpy="1.5708 0 0" />
    <parent
      link="link1" />
    <child
      link="link2" />
    <axis
      xyz="0 0 1" />
    <limit
      lower="-2.7453"
      upper="2.7925"
      effort="200"
      velocity="200" />
  </joint>
  
<link
    name="link3">
    <inertial>
      <origin
        xyz="0.0 0.0 0.0"
        rpy="0 0 0" />
      <mass
        value="2.0" />
      <inertia
        ixx="10"
        ixy="0"
        ixz="0"
        iyy="10"
        iyz="0"
        izz="10" />
    </inertial>
    <visual>
      <origin
        xyz="0 0 0"
        rpy="0 0 0" />
      <geometry>
        <mesh
          filename="link3.STL" />
      </geometry>
      <material
        name="">
        <color
          rgba="0.83 0.83 0.83 1" />
      </material>
    </visual>
    <collision>
      <origin
        xyz="0 0 0"
        rpy="0 0 0" />
      <geometry>
        <mesh
          filename="link3.STL" />
      </geometry>
    </collision>
  </link>

   <joint
    name="joint3"
    type="revolute">
    <origin
      xyz="0 0.444 -0.001"
      rpy="0 0 1.5708" />
    <parent
      link="link2" />
    <child
      link="link3" />
    <axis
      xyz="0 0 1" />
    <limit
      lower="-2.7453"
      upper="2.7925"
      effort="200"
      velocity="200" />
  </joint>

  <link
    name="link4">
    <inertial>
      <origin
        xyz="0.0 0.0 0.0"
        rpy="0 0 0" />
      <mass
        value="2.0" />
      <inertia
        ixx="10"
        ixy="0"
        ixz="0"
        iyy="10"
        iyz="0"
        izz="10" />
    </inertial>
    <visual>
      <origin
        xyz="0 0 0"
        rpy="0 0 0" />
      <geometry>
        <mesh
          filename="link4.STL" />
      </geometry>
      <material
        name="">
        <color
          rgba="0.83 0.83 0.83 1" />
      </material>
    </visual>
    <collision>
      <origin
        xyz="0 0 0"
        rpy="0 0 0" />
      <geometry>
        <mesh
          filename="link4.STL" />
      </geometry>
    </collision>
  </link>

   <joint
    name="joint4"
    type="revolute">
    <origin
      xyz="0.10998 -0.09701 -0.08498"
      rpy="1.5708 0 0" />
    <parent
      link="link3" />
    <child
      link="link4" />
    <axis
      xyz="0 0 1" />
    <limit
      lower="-2.7453"
      upper="2.7925"
      effort="200"
      velocity="200" />
  </joint>

  <link
    name="link5">
    <inertial>
      <origin
        xyz="0.0 0.0 0.0"
        rpy="0 0 0" />
      <mass
        value="2.0" />
      <inertia
        ixx="10"
        ixy="0"
        ixz="0"
        iyy="10"
        iyz="0"
        izz="10" />
    </inertial>
    <visual>
      <origin
        xyz="0 0 0"
        rpy="0 0 0" />
      <geometry>
        <mesh
          filename="link5.STL" />
      </geometry>
      <material
        name="">
        <color
          rgba="0.83 0.83 0.83 1" />
      </material>
    </visual>
    <collision>
      <origin
        xyz="0 0 0"
        rpy="0 0 0" />
      <geometry>
        <mesh
          filename="link5.STL" />
      </geometry>
    </collision>
  </link>

   <joint
    name="joint5"
    type="revolute">
    <origin
      xyz="0.0 0.0 0.37302"
      rpy="-1.5708 0 0" />
    <parent
      link="link4" />
    <child
      link="link5" />
    <axis
      xyz="0 0 1" />
    <limit
      lower="-2.7453"
      upper="2.7925"
      effort="200"
      velocity="200" />
  </joint>

   <link
    name="link6">
    <inertial>
      <origin
        xyz="0.0 0.0 0.0"
        rpy="0 0 0" />
      <mass
        value="2.0" />
      <inertia
        ixx="10"
        ixy="0"
        ixz="0"
        iyy="10"
        iyz="0"
        izz="10" />
    </inertial>
    <visual>
      <origin
        xyz="0 0 0"
        rpy="0 0 0" />
      <geometry>
        <mesh
          filename="link6.STL" />
      </geometry>
      <material
        name="">
        <color
          rgba="0.83 0.83 0.83 1" />
      </material>
    </visual>
    <collision>
      <origin
        xyz="0 0 0"
        rpy="0 0 0" />
      <geometry>
        <mesh
          filename="link6.STL" />
      </geometry>
    </collision>
  </link>

   <joint
    name="joint6"
    type="revolute">
    <origin
      xyz="0.08 -0.06838 0.0"
      rpy="1.5708 0 0" />
    <parent
      link="link5" />
    <child
      link="link6" />
    <axis
      xyz="0 0 1" />
    <limit
      lower="-2.7453"
      upper="2.7925"
      effort="200"
      velocity="200" />
  </joint>

  <link
    name="end_effector">
    <inertial>
      <origin
        xyz="0.0 0.0 0.0"
        rpy="0 0 0" />
      <mass
        value="2.0" />
      <inertia
        ixx="10"
        ixy="0"
        ixz="0"
        iyy="10"
        iyz="0"
        izz="10" />
    </inertial>
    <visual>
      <origin
        xyz="0 0 0"
        rpy="0 0 0" />
      <geometry>
        <mesh
          filename="end_effector.STL" />
      </geometry>
      <material
        name="">
        <color
          rgba="0.83 0.83 0.83 1" />
      </material>
    </visual>
    <collision>
      <origin
        xyz="0 0 0"
        rpy="0 0 0" />
      <geometry>
        <mesh
          filename="end_effector.STL" />
      </geometry>
    </collision>
  </link>

   <joint
    name="joint7"
    type="fixed">
    <origin
      xyz="0 -0.1527 0.1261"
      rpy="1.5708 -1.5708 0" />
    <parent
      link="link6" />
    <child
      link="end_effector" />
    <axis
      xyz="0 0 1" />
    <limit
      lower="-2.7453"
      upper="2.7925"
      effort="200"
      velocity="200" />
  </joint>


   </robot>